<?xml version="1.0"?>
<robot name="my_robot">
    <material name="blue">
        <color rgba="0 0 0.5 1"/>
    </material>
    <material name="grey">
        <color rgba="0.5 0.5 0.5 1"/>
    </material>
    <link name="base_link">
        <visual>
            <geometry>
                <box size="0.6 0.4 0.2" />
            </geometry>
            <origin xyz="0 0 0.1" rpy="0 0 0" />
            <material name="blue"/>
        </visual>
    </link>
    <link name="second_link">
        <visual>
            <geometry>
                <cylinder radius="0.1" length="0.2" />
            </geometry>
            <origin xyz="0 0 0.1" rpy="0 0 0" />
            <material name="grey"/>
        </visual>
    </link>
    <link name="third_link">
        <visual>
            <geometry>
                <box size="0.1 0.1 0.1" />
            </geometry>
            <origin xyz="0 0 0.05" rpy="0 0 0" />
            <material name="grey"/>
        </visual>
    </link>

    <link name="right_rear_wheel_link">
        <visual>
            <geometry>
                <cylinder radius="0.1" length="0.05" />
            </geometry>
            <origin xyz="0 0 0" rpy="1.57 0 0" />
            <material name="grey"/>
        </visual>
    </link>

    <link name="right_front_wheel_link">
        <visual>
            <geometry>
                <cylinder radius="0.1" length="0.05" />
            </geometry>
            <origin xyz="0 0 0" rpy="1.57 0 0" />
            <material name="grey"/>
        </visual>
    </link>

    <link name="left_rear_wheel_link">
        <visual>
            <geometry>
                <cylinder radius="0.1" length="0.05" />
            </geometry>
            <origin xyz="0 0 0" rpy="1.57 0 0" />
            <material name="grey"/>
        </visual>
    </link>

    <link name="left_front_wheel_link">
        <visual>
            <geometry>
                <cylinder radius="0.1" length="0.05" />
            </geometry>
            <origin xyz="0 0 0" rpy="1.57 0 0" />
            <material name="grey"/>
        </visual>
    </link>

    <joint name="base_second_joint" type="fixed">
        <parent link="base_link"/>
        <child link="second_link"/>
        <origin xyz="0 0 0.2" rpy="0 0 0"/>
        <!-- <axis xyz="0 0 1"/>
        <limit lower="-1.57" upper="1.57" effort="10" velocity="1"/> -->
    </joint>
    <!-- <joint name="base_third_joint" type="revolute">
        <parent link="second_link"/>
        <child link="third_link"/>
        <origin xyz="0 0 0.2" rpy="0 0 0"/>
        <axis xyz="0 0 1"/>
        <limit lower="-1.57" upper="1.57" effort="10" velocity="1"/>
    </joint> -->

    <!-- <joint name="base_third_joint" type="continuous">
        <parent link="second_link"/>
        <child link="third_link"/>
        <origin xyz="0 0 0.2" rpy="0 0 0"/>
        <axis xyz="0 0 1"/>
    </joint> -->

    <joint name="base_third_joint" type="prismatic">
        <parent link="second_link"/>
        <child link="third_link"/>
        <origin xyz="0 0 0.2" rpy="0 0 0"/>
        <axis xyz="0 0 1"/>
        <limit lower="0.0" upper="0.2" effort="10" velocity="0.1"/>
    </joint>

    <!-- Adding a Wheel -->
    <joint name="base_right_rear_wheel_joint" type="continuous">
        <parent link="base_link"/>
        <child link="right_rear_wheel_link"/>
        <origin xyz="-0.15 -0.2 0" rpy="0 0 0"/>
        <axis xyz="0 1 0"/>
    </joint>

    <joint name="base_right_front_wheel_joint" type="continuous">
        <parent link="base_link"/>
        <child link="right_front_wheel_link"/>
        <origin xyz="0.15 -0.2 0" rpy="0 0 0"/>
        <axis xyz="0 1 0"/>
    </joint>

    <joint name="base_left_rear_wheel_joint" type="continuous">
        <parent link="base_link"/>
        <child link="left_rear_wheel_link"/>
        <origin xyz="-0.15 0.2 0" rpy="0 0 0"/>
        <axis xyz="0 1 0"/>
    </joint>

    <joint name="base_left_front_wheel_joint" type="continuous">
        <parent link="base_link"/>
        <child link="left_front_wheel_link"/>
        <origin xyz="0.15 0.2 0" rpy="0 0 0"/>
        <axis xyz="0 1 0"/>
    </joint>


</robot>